Workbook
Name acc.accountNo: #REF!
Name acc.aliasName: #REF!
Name acc.availableBalance: #REF!
Name acc.currency: #REF!
Name acc.interestRate: #REF!
Name acc.openDate: #REF!
Name acc.statusname: #REF!
Name Fx: #REF!
Name Fx: '>>Chart'!$C$1
Name Fx_rate: #REF!
Name Fx_rate: #REF!
Name Fx_rate: Summary!$B$3
Name KeywordsTable: #REF!
Name NGÂN_HÀNG_TMCP_CÔNG_THƯƠNG_VIỆT_NAM: #REF!
Name ROW___ROW_A10: #REF!
Name ROW___ROW_A25: #REF!

Sheet for email
B4: BW Industrial Development JSC
B5: Floor 17, Becamex Tower, 230 Binh Duong Boulevard,
B6: Phu Hoa Ward, Thu Dau Mot City, Binh Duong Province, Vietnam
B7: SUMMARY | F7: =F89-F106 -> 0
C8: From 22-Feb-2021 to 28-Feb-2021 | G8: From 08-Feb-2021 to 21-Feb-2021 | K8: Var | N8: From 08-Feb-2021
C9: BWID JSC | D9: VIETCO3 | E9: Subsidiaries | G9: BWID JSC | H9: VietCo3 | I9: Subsidiaries | K9: BWID JSC | L9: VietCo3 | M9: Subsidiaries
C10: Equivalent to VND bn | D10: Equivalent to VND bn | E10: Equivalent to VND bn | G10: Equivalent to VND bn | H10: Equivalent to VND bn | I10: Equivalent to VND bn | K10: Equivalent to VND bn | L10: Equivalent to VND bn | M10: Equivalent to VND bn
B11: ACTUAL
B12: Opening balance | C12: #REF! | D12: #REF! | E12: #REF! | G12: 795.97527 | H12: 0.41238947 | I12: 495.65174 | K12: =C12-G12 -> #REF! | L12: =D12-H12 -> #REF! | M12: =E12-I12 -> #REF!
B13: Cash in | C13: =SUM(C14:C15) -> 22.066935 | D13: =SUM(D14:D15) -> 2.2534909 | E13: =SUM(E14:E15) -> 114.0661 | G13: 1.1986464 | H13: 110.503 | I13: 524.29885 | K13: =C13-G13 -> 20.868288 | L13: =D13-H13 -> -108.24951 | M13: =E13-I13 -> -410.23276
B14: Rental income and bank interest | C14: 22.066935 | D14: 2.2534909 | E14: 40.771099 | G14: 1.1986464 | H14: 0 | I14: 3.5326552
B15: Shareholder loan transfer | C15: 0 | D15: 0 | E15: 73.295 | G15: 0 | H15: 110.503 | I15: 520.7662
B16: Loan drawdown
B18: Cash out | C18: =SUM(C19:C23) -> 38.055948 | D18: =SUM(D19:D23) -> 60.957728 | E18: =SUM(E19:E23) -> 132.88481 | G18: 111.56871 | H18: 110.4042 | I18: 518.58906 | K18: =C18-G18 -> -73.51276 | L18: =D18-H18 -> -49.446471 | M18: =E18-I18 -> -385.70425
B19: Land lease price payment | C19: 0 | D19: 0 | E19: 0.44709496 | G19: 0 | H19: 0 | I19: 105.38667
B20: Deal payment | C20: 0 | D20: 0 | E20: 0 | G20: 0 | H20: 0 | I20: 0
B21: Construction expense | C21: 0 | D21: 0 | E21: 36.599596 | G21: 0 | H21: 0 | I21: 2.6932629
B22: Others (G&A expenses, bank charge…) | C22: 38.055948 | D22: 21.210228 | E22: 62.290621 | G22: 1.065708 | H22: 0.0041998 | I22: 0.14293196
B23: Shareholder loan transfer | C23: 0 | D23: 39.7475 | E23: 33.5475 | G23: 110.503 | H23: 110.4 | I23: 410.3662
B25: Closing balance | C25: #REF! | D25: #REF! | E25: #REF! | G25: 795.97527 | H25: 0.41238947 | I25: 495.65174 | K25: =C25-G25 -> #REF! | L25: =D25-H25 -> #REF! | M25: =E25-I25 -> #REF!
B27: PLANNING FOR NEXT WEEK
B28: Opening balance | C28: =C25 -> #REF! | D28: =D25 -> #REF! | E28: =E25 -> #REF! | G28: 685.6052 | H28: 0.51118967 | I28: 502.62213 | K28: =C28-G28 -> #REF! | L28: =D28-H28 -> #REF! | M28: =E28-I28 -> #REF!
B29: Cash in | C29: =SUM(C30:C31) -> #REF! | D29: =SUM(D30:D31) -> #REF! | E29: =SUM(E30:E31) -> #REF! | G29: 31.608491 | H29: 0 | I29: 1.1273873 | K29: =C29-G29 -> #REF! | L29: =D29-H29 -> #REF! | M29: =E29-I29 -> #REF!
B30: - From tenants | C30: #REF! | D30: #REF! | E30: #REF! | G30: 24.470491 | H30: 0 | I30: 1.1273873 | K30: =C30-G30 -> #REF! | L30: =D30-H30 -> #REF! | M30: =E30-I30 -> #REF!
B31: - Refinancing | C31: #REF! | D31: 0 | E31: 0 | G31: 7.138 | H31: 0 | I31: 0 | K31: =C31-G31 -> #REF! | L31: =D31-H31 -> 0 | M31: =E31-I31 -> 0
B32: - Loan drawdown | K32: =C32-G32 -> 0 | L32: =D32-H32 -> 0 | M32: =E32-I32 -> 0
B33: Significant cash out | C33: =C35 -> #REF! | D33: =D35 -> 0 | E33: =E35 -> #REF! | G33: 125.52862 | H33: 0 | I33: 175.64445 | K33: =C33-G33 -> #REF! | L33: =D33-H33 -> 0 | M33: =E33-I33 -> #REF!
B34: - For investment deals | K34: =C34-G34 -> 0 | L34: =D34-H34 -> 0 | M34: =E34-I34 -> 0
B35: - For construction | C35: #REF! | D35: 0 | E35: #REF! | G35: 125.52862 | H35: 0 | I35: 175.64445 | K35: =C35-G35 -> #REF! | L35: =D35-H35 -> 0 | M35: =E35-I35 -> #REF!
B36: Surplus (+)/ Shortage (-) | C36: =C28+C29-C33 -> #REF! | D36: =D28+D29-D33 -> #REF! | E36: =E28+E29-E33 -> #REF! | G36: 591.68507 | H36: 0.51118967 | I36: 328.10507 | K36: =C36-G36 -> #REF! | L36: =D36-H36 -> #REF! | M36: =E36-I36 -> #REF!
C39: From 1-May-2024 to 18-May-2024 | G39: From 16-Apr-2024 to 30-Apr-2024 | K39: Variance
C40: BWID JSC | D40: VIETCO3 | E40: Subsidiaries | F40: Total | G40: BWID JSC | H40: VIETCO3 | I40: Subsidiaries | J40: Total | K40: BWID JSC | L40: VIETCO3 | M40: Subsidiaries | N40: Total
C41: Equivalent to USD mn | D41: Equivalent to USD mn | E41: Equivalent to USD mn | F41: Equivalent to USD mn | G41: Equivalent to USD mn | H41: Equivalent to USD mn | I41: Equivalent to USD mn | J41: Equivalent to USD mn | K41: Equivalent to USD mn | L41: Equivalent to USD mn | M41: Equivalent to USD mn | N41: Equivalent to USD mn
B42: ACTUAL
B43: Opening balance | C43: =G77-C110 -> 6.9899194 | D43: =H77-D110 -> 9.7598303 | E43: =I77-E110 -> 68.245747 | F43: =SUM(C43:E43) -> 84.995497 | G43: 6.9991763 | H43: 8.3059755 | I43: 76.97239 | J43: 92.277542 | O43: =F43+F75-Summary!E77 -> -49.525552
B45: Cash in | C45: =SUM(C47:C59) -> 2.3013678 | D45: =SUM(D47:D59) -> 52.043071 | E45: =SUM(E47:E59) -> 18.406773 | F45: =SUM(F47:F59) -> 72.751212 | G45: 2.6427603 | H45: 7.6943171 | I45: 46.043402 | J45: 56.380479 | K45: =C45-G45 -> -0.34139243 | L45: =D45-H45 -> 44.348754 | M45: =E45-I45 -> -27.636629 | N45: =F45-J45 -> 16.370733
B46: Actual Cash IN | C46: =C45-C49-C53-C54 -> 0.0091042269 | D46: =D45-D49-D53-D54 -> 0.2487225 | E46: =E45-E49-E53-E54 -> 12.413848 | F46: =F45-F49-F53-F54 -> 12.671675 | G46: 0.33506796 | H46: 0.010776304 | I46: 10.591504 | J46: 10.937348 | K46: =C46-G46 -> -0.32596373 | L46: =D46-H46 -> 0.2379462 | M46: =E46-I46 -> 1.8223441 | N46: =F46-J46 -> 1.7343265
B47: Receipt from tenants | C47: =IFERROR(VLOOKUP($B47,Summary!$A$80:$D$94,2,0),0) -> 0 | D47: =IFERROR(VLOOKUP($B47,Summary!$A$80:$D$94,3,0),0) -> 0.23338632 | E47: =IFERROR(VLOOKUP($B47,Summary!$A$80:$D$94,4,0),0) -> 12.252736 | F47: =SUM(C47:E47) -> 12.486122 | G47: 0.32124667 | H47: 0 | I47: 10.446865 | J47: 10.768112 | K47: =C47-G47 -> -0.32124667 | L47: =D47-H47 -> 0.23338632 | M47: =E47-I47 -> 1.8058709 | N47: =F47-J47 -> 1.7180105
B48: Refund land/deal deposit payment | C48: =IFERROR(VLOOKUP($B48,Summary!$A$80:$D$94,2,0),0) -> 0 | D48: =IFERROR(VLOOKUP($B48,Summary!$A$80:$D$94,3,0),0) -> 0 | E48: =IFERROR(VLOOKUP($B48,Summary!$A$80:$D$94,4,0),0) -> 0 | F48: =SUM(C48:E48) -> 0 | G48: 0 | H48: 0 | I48: 0 | J48: 0 | K48: =C48-G48 -> 0 | L48: =D48-H48 -> 0 | M48: =E48-I48 -> 0 | N48: =F48-J48 -> 0
B49: Internal transfer in | C49: =IFERROR(VLOOKUP($B49,Summary!$A$80:$D$94,2,0),0) -> 2.2922636 | D49: =IFERROR(VLOOKUP($B49,Summary!$A$80:$D$94,3,0),0) -> 51.794349 | E49: =IFERROR(VLOOKUP($B49,Summary!$A$80:$D$94,4,0),0) -> 5.9929246 | F49: =SUM(C49:E49) -> 60.079537 | G49: 2.3076923 | H49: 7.6835408 | I49: 35.451898 | J49: 45.443131 | K49: =C49-G49 -> -0.015428697 | L49: =D49-H49 -> 44.110808 | M49: =E49-I49 -> -29.458973 | N49: =F49-J49 -> 14.636406
...

Sheet >>Chart
C1: =Fx_rate -> 26175 | D1: BWID JSC | E1: BWID JSC | F1: BWID JSC | G1: VC3 | H1: VC3 | I1: VC3 | J1: VC3 | K1: Subsidiaries | L1: Subsidiaries | M1: Subsidiaries | N1: TOTAL
C2: Bank | D2: BW_VND_bn | E2: BW_USD_mn | F2: BW_Total_USD_mn | G2: VC3_VND_bn | H2: VC3_USD_mn | I2: VC3_Total_USD_mn | J2: VC3_Total_VND (bn) | K2: SUB_VND_bn | L2: SUB_USD_mn | M2: SUB_TOTAL_USD_mn | N2: VND | O2: USD | P2: Total | Q2: CREDIT FACILITY | R2: OUT. LOAN BALANCE @30/11/22 | S2: %
S3: %
C4: VIETINBANK - TIEN SON | D4: =SUMIFS('Cash Balance'!$L$4:$L$920,'Cash Balance'!$Y$4:$Y$920,'>>Chart'!$C4,'Cash Balance'!$W$4:$W$920,'>>Chart'!D$1)/1000000000 -> 0.029039515 | E4: =SUMIFS('Cash Balance'!$T$4:$T$920,'Cash Balance'!$Y$4:$Y$920,'>>Chart'!$C4,'Cash Balance'!$W$4:$W$920,'>>Chart'!E$1)/1000000 -> 0.0002 | F4: {=D4*1000/Fx+E4} -> 0.0013094371 | G4: =SUMIFS('Cash Balance'!$L$4:$L$920,'Cash Balance'!$Y$4:$Y$920,'>>Chart'!$C4,'Cash Balance'!$W$4:$W$920,'>>Chart'!G$1)/1000000000 -> 261.65697 | H4: =SUMIFS('Cash Balance'!$T$4:$T$920,'Cash Balance'!$Y$4:$Y$920,'>>Chart'!$C4,'Cash Balance'!$W$4:$W$920,'>>Chart'!H$1)/1000000 -> 0.00043853 | I4: =G4/Fx*1000+H4 -> 9.9968845 | J4: =G4+H4*Fx/1000 -> 261.66845 | K4: =SUMIFS('Cash Balance'!$L$4:$L$920,'Cash Balance'!$Y$4:$Y$920,'>>Chart'!$C4,'Cash Balance'!$W$4:$W$920,'>>Chart'!K$1)/1000000000 -> 538.68454 | L4: =SUMIFS('Cash Balance'!$T$4:$T$920,'Cash Balance'!$Y$4:$Y$920,'>>Chart'!$C4,'Cash Balance'!$W$4:$W$920,'>>Chart'!L$1)/1000000 -> 0.03067331 | M4: =K4*1000/Fx+L4 -> 20.61079 | N4: =D4+G4+K4 -> 800.37055 | O4: =E4+H4+L4 -> 0.03131184 | P4: =N4*1000/Fx+O4 -> 30.608983 | Q4: =SUMIFS(#REF!,#REF!,'>>Chart'!C4) -> #REF! | R4: =SUMIFS(#REF!,#REF!,'>>Chart'!C4) -> #REF! | S4: =Q4/$Q$18 -> #REF!
C5: VIETINBANK - CN1 | D5: =SUMIFS('Cash Balance'!$L$4:$L$920,'Cash Balance'!$Y$4:$Y$920,'>>Chart'!$C5,'Cash Balance'!$W$4:$W$920,'>>Chart'!D$1)/1000000000 -> 0.0908675 | E5: =SUMIFS('Cash Balance'!$T$4:$T$920,'Cash Balance'!$Y$4:$Y$920,'>>Chart'!$C5,'Cash Balance'!$W$4:$W$920,'>>Chart'!E$1)/1000000 -> 0.00074833 | F5: =D5*1000/Fx+E5 -> 0.0042198677 | G5: =SUMIFS('Cash Balance'!$L$4:$L$920,'Cash Balance'!$Y$4:$Y$920,'>>Chart'!$C5,'Cash Balance'!$W$4:$W$920,'>>Chart'!G$1)/1000000000 -> 0.17254312 | H5: =SUMIFS('Cash Balance'!$T$4:$T$920,'Cash Balance'!$Y$4:$Y$920,'>>Chart'!$C5,'Cash Balance'!$W$4:$W$920,'>>Chart'!H$1)/1000000 -> 0.00054176 | I5: =G5/Fx*1000+H5 -> 0.0071336651 | J5: =G5+H5*Fx/1000 -> 0.18672368 | K5: =SUMIFS('Cash Balance'!$L$4:$L$920,'Cash Balance'!$Y$4:$Y$920,'>>Chart'!$C5,'Cash Balance'!$W$4:$W$920,'>>Chart'!K$1)/1000000000 -> 58.610553 | L5: =SUMIFS('Cash Balance'!$T$4:$T$920,'Cash Balance'!$Y$4:$Y$920,'>>Chart'!$C5,'Cash Balance'!$W$4:$W$920,'>>Chart'!L$1)/1000000 -> 0 | M5: =K5*1000/Fx+L5 -> 2.2391806 | N5: =D5+G5+K5 -> 58.873963 | O5: =E5+H5+L5 -> 0.00129009 | P5: =N5*1000/Fx+O5 -> 2.2505342 | Q5: =SUMIFS(#REF!,#REF!,'>>Chart'!C5) -> #REF! | R5: =SUMIFS(#REF!,#REF!,'>>Chart'!C5) -> #REF! | S5: =Q5/$Q$18 -> #REF!
C6: VIETINBANK - BINH DUONG + QM | D6: =SUMIFS('Cash Balance'!$L$4:$L$920,'Cash Balance'!$Y$4:$Y$920,'>>Chart'!$C6,'Cash Balance'!$W$4:$W$920,'>>Chart'!D$1)/1000000000 -> 6.9729213 | E6: =SUMIFS('Cash Balance'!$T$4:$T$920,'Cash Balance'!$Y$4:$Y$920,'>>Chart'!$C6,'Cash Balance'!$W$4:$W$920,'>>Chart'!E$1)/1000000 -> 0.00170392 | F6: =D6*1000/Fx+E6 -> 0.26810015 | G6: =SUMIFS('Cash Balance'!$L$4:$L$920,'Cash Balance'!$Y$4:$Y$920,'>>Chart'!$C6,'Cash Balance'!$W$4:$W$920,'>>Chart'!G$1)/1000000000 -> 110.4278 | H6: =SUMIFS('Cash Balance'!$T$4:$T$920,'Cash Balance'!$Y$4:$Y$920,'>>Chart'!$C6,'Cash Balance'!$W$4:$W$920,'>>Chart'!H$1)/1000000 -> 0.00181222 | I6: =G6/Fx*1000+H6 -> 4.2206393 | J6: =G6+H6*Fx/1000 -> 110.47523 | K6: =SUMIFS('Cash Balance'!$L$4:$L$920,'Cash Balance'!$Y$4:$Y$920,'>>Chart'!$C6,'Cash Balance'!$W$4:$W$920,'>>Chart'!K$1)/1000000000 -> 427.3377 | L6: =SUMIFS('Cash Balance'!$T$4:$T$920,'Cash Balance'!$Y$4:$Y$920,'>>Chart'!$C6,'Cash Balance'!$W$4:$W$920,'>>Chart'!L$1)/1000000 -> 0 | M6: =K6*1000/Fx+L6 -> 16.326178 | N6: =D6+G6+K6 -> 544.73842 | O6: =E6+H6+L6 -> 0.00351614 | P6: =N6*1000/Fx+O6 -> 20.814917 | Q6: =SUMIFS(#REF!,#REF!,'>>Chart'!C6) -> #REF! | R6: =SUMIFS(#REF!,#REF!,'>>Chart'!C6) -> #REF! | S6: =Q6/$Q$18 -> #REF!
C7: VIETINBANK - DONG SAI GON | D7: =SUMIFS('Cash Balance'!$L$4:$L$920,'Cash Balance'!$Y$4:$Y$920,'>>Chart'!$C7,'Cash Balance'!$W$4:$W$920,'>>Chart'!D$1)/1000000000 -> 0 | E7: =SUMIFS('Cash Balance'!$T$4:$T$920,'Cash Balance'!$Y$4:$Y$920,'>>Chart'!$C7,'Cash Balance'!$W$4:$W$920,'>>Chart'!E$1)/1000000 -> 0.000769 | F7: =D7*1000/Fx+E7 -> 0.000769 | G7: =SUMIFS('Cash Balance'!$L$4:$L$920,'Cash Balance'!$Y$4:$Y$920,'>>Chart'!$C7,'Cash Balance'!$W$4:$W$920,'>>Chart'!G$1)/1000000000 -> 0.004095449 | H7: =SUMIFS('Cash Balance'!$T$4:$T$920,'Cash Balance'!$Y$4:$Y$920,'>>Chart'!$C7,'Cash Balance'!$W$4:$W$920,'>>Chart'!H$1)/1000000 -> 0 | I7: =G7/Fx*1000+H7 -> 0.00015646415 | J7: =G7+H7*Fx/1000 -> 0.004095449 | K7: =SUMIFS('Cash Balance'!$L$4:$L$920,'Cash Balance'!$Y$4:$Y$920,'>>Chart'!$C7,'Cash Balance'!$W$4:$W$920,'>>Chart'!K$1)/1000000000 -> 105.91062 | L7: =SUMIFS('Cash Balance'!$T$4:$T$920,'Cash Balance'!$Y$4:$Y$920,'>>Chart'!$C7,'Cash Balance'!$W$4:$W$920,'>>Chart'!L$1)/1000000 -> 0 | M7: =K7*1000/Fx+L7 -> 4.0462508 | N7: =D7+G7+K7 -> 105.91471 | O7: =E7+H7+L7 -> 0.000769 | P7: =N7*1000/Fx+O7 -> 4.0471763 | Q7: =SUMIFS(#REF!,#REF!,'>>Chart'!C7) -> #REF! | R7: =SUMIFS(#REF!,#REF!,'>>Chart'!C7) -> #REF! | S7: =Q7/$Q$18 -> #REF!
C8: VIETCOMBANK - BA DINH | D8: =SUMIFS('Cash Balance'!$L$4:$L$920,'Cash Balance'!$Y$4:$Y$920,'>>Chart'!$C8,'Cash Balance'!$W$4:$W$920,'>>Chart'!D$1)/1000000000 -> 0.42946304 | E8: =SUMIFS('Cash Balance'!$T$4:$T$920,'Cash Balance'!$Y$4:$Y$920,'>>Chart'!$C8,'Cash Balance'!$W$4:$W$920,'>>Chart'!E$1)/1000000 -> 0.00064269 | F8: =D8*1000/Fx+E8 -> 0.017050065 | G8: =SUMIFS('Cash Balance'!$L$4:$L$920,'Cash Balance'!$Y$4:$Y$920,'>>Chart'!$C8,'Cash Balance'!$W$4:$W$920,'>>Chart'!G$1)/1000000000 -> 2.0349262 | H8: =SUMIFS('Cash Balance'!$T$4:$T$920,'Cash Balance'!$Y$4:$Y$920,'>>Chart'!$C8,'Cash Balance'!$W$4:$W$920,'>>Chart'!H$1)/1000000 -> 0.0006062 | I8: =G8/Fx*1000+H8 -> 0.078349322 | J8: =G8+H8*Fx/1000 -> 2.0507935 | K8: =SUMIFS('Cash Balance'!$L$4:$L$920,'Cash Balance'!$Y$4:$Y$920,'>>Chart'!$C8,'Cash Balance'!$W$4:$W$920,'>>Chart'!K$1)/1000000000 -> 119.04302 | L8: =SUMIFS('Cash Balance'!$T$4:$T$920,'Cash Balance'!$Y$4:$Y$920,'>>Chart'!$C8,'Cash Balance'!$W$4:$W$920,'>>Chart'!L$1)/1000000 -> 0 | M8: =K8*1000/Fx+L8 -> 4.5479666 | N8: =D8+G8+K8 -> 121.50741 | O8: =E8+H8+L8 -> 0.00124889 | P8: =N8*1000/Fx+O8 -> 4.643366 | Q8: =SUMIFS(#REF!,#REF!,'>>Chart'!C8) -> #REF! | R8: =SUMIFS(#REF!,#REF!,'>>Chart'!C8) -> #REF! | S8: =Q8/$Q$18 -> #REF!
C9: VIETCOMBANK - HCM | D9: =SUMIFS('Cash Balance'!$L$4:$L$920,'Cash Balance'!$Y$4:$Y$920,'>>Chart'!$C9,'Cash Balance'!$W$4:$W$920,'>>Chart'!D$1)/1000000000 -> 0.28224182 | E9: =SUMIFS('Cash Balance'!$T$4:$T$920,'Cash Balance'!$Y$4:$Y$920,'>>Chart'!$C9,'Cash Balance'!$W$4:$W$920,'>>Chart'!E$1)/1000000 -> 0.00106836 | F9: =D9*1000/Fx+E9 -> 0.011851238 | G9: =SUMIFS('Cash Balance'!$L$4:$L$920,'Cash Balance'!$Y$4:$Y$920,'>>Chart'!$C9,'Cash Balance'!$W$4:$W$920,'>>Chart'!G$1)/1000000000 -> 1267.8364 | H9: =SUMIFS('Cash Balance'!$T$4:$T$920,'Cash Balance'!$Y$4:$Y$920,'>>Chart'!$C9,'Cash Balance'!$W$4:$W$920,'>>Chart'!H$1)/1000000 -> 9.25e-05 | I9: =G9/Fx*1000+H9 -> 48.437015 | J9: =G9+H9*Fx/1000 -> 1267.8389 | K9: =SUMIFS('Cash Balance'!$L$4:$L$920,'Cash Balance'!$Y$4:$Y$920,'>>Chart'!$C9,'Cash Balance'!$W$4:$W$920,'>>Chart'!K$1)/1000000000 -> 171.24825 | L9: =SUMIFS('Cash Balance'!$T$4:$T$920,'Cash Balance'!$Y$4:$Y$920,'>>Chart'!$C9,'Cash Balance'!$W$4:$W$920,'>>Chart'!L$1)/1000000 -> 0.00558932 | M9: =K9*1000/Fx+L9 -> 6.548025 | N9: =D9+G9+K9 -> 1439.3669 | O9: =E9+H9+L9 -> 0.00675018 | P9: =N9*1000/Fx+O9 -> 54.996891 | Q9: =SUMIFS(#REF!,#REF!,'>>Chart'!C9) -> #REF! | R9: =SUMIFS(#REF!,#REF!,'>>Chart'!C9) -> #REF! | S9: =Q9/$Q$18 -> #REF!
C10: BIDV - THANH XUAN | D10: =SUMIFS('Cash Balance'!$L$4:$L$920,'Cash Balance'!$Y$4:$Y$920,'>>Chart'!$C10,'Cash Balance'!$W$4:$W$920,'>>Chart'!D$1)/1000000000 -> 0.038060079 | E10: =SUMIFS('Cash Balance'!$T$4:$T$920,'Cash Balance'!$Y$4:$Y$920,'>>Chart'!$C10,'Cash Balance'!$W$4:$W$920,'>>Chart'!E$1)/1000000 -> 6.48e-05 | F10: =D10*1000/Fx+E10 -> 0.0015188622 | G10: =SUMIFS('Cash Balance'!$L$4:$L$920,'Cash Balance'!$Y$4:$Y$920,'>>Chart'!$C10,'Cash Balance'!$W$4:$W$920,'>>Chart'!G$1)/1000000000 -> 5.4521297 | H10: =SUMIFS('Cash Balance'!$T$4:$T$920,'Cash Balance'!$Y$4:$Y$920,'>>Chart'!$C10,'Cash Balance'!$W$4:$W$920,'>>Chart'!H$1)/1000000 -> 0.00021161 | I10: =G10/Fx*1000+H10 -> 0.20850692 | J10: =G10+H10*Fx/1000 -> 5.4576686 | K10: =SUMIFS('Cash Balance'!$L$4:$L$920,'Cash Balance'!$Y$4:$Y$920,'>>Chart'!$C10,'Cash Balance'!$W$4:$W$920,'>>Chart'!K$1)/1000000000 -> 288.1883 | L10: =SUMIFS('Cash Balance'!$T$4:$T$920,'Cash Balance'!$Y$4:$Y$920,'>>Chart'!$C10,'Cash Balance'!$W$4:$W$920,'>>Chart'!L$1)/1000000 -> 0.00016149 | M10: =K10*1000/Fx+L10 -> 11.010221 | N10: =D10+G10+K10 -> 293.67849 | O10: =E10+H10+L10 -> 0.0004379 | P10: =N10*1000/Fx+O10 -> 11.220247 | Q10: =SUMIFS(#REF!,#REF!,'>>Chart'!C10) -> #REF! | R10: =SUMIFS(#REF!,#REF!,'>>Chart'!C10) -> #REF! | S10: =Q10/$Q$18 -> #REF!
C11: BIDV - NAM SAI GON | D11: =SUMIFS('Cash Balance'!$L$4:$L$920,'Cash Balance'!$Y$4:$Y$920,'>>Chart'!$C11,'Cash Balance'!$W$4:$W$920,'>>Chart'!D$1)/1000000000 -> 0 | E11: =SUMIFS('Cash Balance'!$T$4:$T$920,'Cash Balance'!$Y$4:$Y$920,'>>Chart'!$C11,'Cash Balance'!$W$4:$W$920,'>>Chart'!E$1)/1000000 -> 0 | F11: =D11*1000/Fx+E11 -> 0 | G11: =SUMIFS('Cash Balance'!$L$4:$L$920,'Cash Balance'!$Y$4:$Y$920,'>>Chart'!$C11,'Cash Balance'!$W$4:$W$920,'>>Chart'!G$1)/1000000000 -> 0 | H11: =SUMIFS('Cash Balance'!$T$4:$T$920,'Cash Balance'!$Y$4:$Y$920,'>>Chart'!$C11,'Cash Balance'!$W$4:$W$920,'>>Chart'!H$1)/1000000 -> 0 | I11: =G11/Fx*1000+H11 -> 0 | J11: =G11+H11*Fx/1000 -> 0 | K11: =SUMIFS('Cash Balance'!$L$4:$L$920,'Cash Balance'!$Y$4:$Y$920,'>>Chart'!$C11,'Cash Balance'!$W$4:$W$920,'>>Chart'!K$1)/1000000000 -> 82.158268 | L11: =SUMIFS('Cash Balance'!$T$4:$T$920,'Cash Balance'!$Y$4:$Y$920,'>>Chart'!$C11,'Cash Balance'!$W$4:$W$920,'>>Chart'!L$1)/1000000 -> 0 | M11: =K11*1000/Fx+L11 -> 3.1388068 | N11: =D11+G11+K11 -> 82.158268 | O11: =E11+H11+L11 -> 0 | P11: =N11*1000/Fx+O11 -> 3.1388068 | Q11: =SUMIFS(#REF!,#REF!,'>>Chart'!C11) -> #REF! | R11: =SUMIFS(#REF!,#REF!,'>>Chart'!C11) -> #REF! | S11: =Q11/$Q$18 -> #REF!
C12: BIDV - LONG BIEN | D12: =SUMIFS('Cash Balance'!$L$4:$L$920,'Cash Balance'!$Y$4:$Y$920,'>>Chart'!$C12,'Cash Balance'!$W$4:$W$920,'>>Chart'!D$1)/1000000000 -> 0 | E12: =SUMIFS('Cash Balance'!$T$4:$T$920,'Cash Balance'!$Y$4:$Y$920,'>>Chart'!$C12,'Cash Balance'!$W$4:$W$920,'>>Chart'!E$1)/1000000 -> 0 | F12: =D12*1000/Fx+E12 -> 0 | G12: =SUMIFS('Cash Balance'!$L$4:$L$920,'Cash Balance'!$Y$4:$Y$920,'>>Chart'!$C12,'Cash Balance'!$W$4:$W$920,'>>Chart'!G$1)/1000000000 -> 0 | H12: =SUMIFS('Cash Balance'!$T$4:$T$920,'Cash Balance'!$Y$4:$Y$920,'>>Chart'!$C12,'Cash Balance'!$W$4:$W$920,'>>Chart'!H$1)/1000000 -> 0 | I12: =G12/Fx*1000+H12 -> 0 | J12: =G12+H12*Fx/1000 -> 0 | K12: =SUMIFS('Cash Balance'!$L$4:$L$920,'Cash Balance'!$Y$4:$Y$920,'>>Chart'!$C12,'Cash Balance'!$W$4:$W$920,'>>Chart'!K$1)/1000000000 -> 0.1016279 | L12: =SUMIFS('Cash Balance'!$T$4:$T$920,'Cash Balance'!$Y$4:$Y$920,'>>Chart'!$C12,'Cash Balance'!$W$4:$W$920,'>>Chart'!L$1)/1000000 -> 0.0001412 | M12: =K12*1000/Fx+L12 -> 0.0040238321 | N12: =D12+G12+K12 -> 0.1016279 | O12: =E12+H12+L12 -> 0.0001412 | P12: =N12*1000/Fx+O12 -> 0.0040238321 | Q12: =SUMIFS(#REF!,#REF!,'>>Chart'!C12) -> #REF! | R12: =SUMIFS(#REF!,#REF!,'>>Chart'!C12) -> #REF! | S12: =Q12/$Q$18 -> #REF!
C13: OCB - BINH DUONG | D13: =SUMIFS('Cash Balance'!$L$4:$L$920,'Cash Balance'!$Y$4:$Y$920,'>>Chart'!$C13,'Cash Balance'!$W$4:$W$920,'>>Chart'!D$1)/1000000000 -> 0.069627514 | E13: =SUMIFS('Cash Balance'!$T$4:$T$920,'Cash Balance'!$Y$4:$Y$920,'>>Chart'!$C13,'Cash Balance'!$W$4:$W$920,'>>Chart'!E$1)/1000000 -> 0.00015 | F13: =D13*1000/Fx+E13 -> 0.0028100769 | G13: =SUMIFS('Cash Balance'!$L$4:$L$920,'Cash Balance'!$Y$4:$Y$920,'>>Chart'!$C13,'Cash Balance'!$W$4:$W$920,'>>Chart'!G$1)/1000000000 -> 0.056483173 | H13: =SUMIFS('Cash Balance'!$T$4:$T$920,'Cash Balance'!$Y$4:$Y$920,'>>Chart'!$C13,'Cash Balance'!$W$4:$W$920,'>>Chart'!H$1)/1000000 -> 0.0001 | I13: =G13/Fx*1000+H13 -> 0.0022579054 | J13: =G13+H13*Fx/1000 -> 0.059100673 | K13: =SUMIFS('Cash Balance'!$L$4:$L$920,'Cash Balance'!$Y$4:$Y$920,'>>Chart'!$C13,'Cash Balance'!$W$4:$W$920,'>>Chart'!K$1)/1000000000 -> 0.47251851 | L13: =SUMIFS('Cash Balance'!$T$4:$T$920,'Cash Balance'!$Y$4:$Y$920,'>>Chart'!$C13,'Cash Balance'!$W$4:$W$920,'>>Chart'!L$1)/1000000 -> 0 | M13: =K13*1000/Fx+L13 -> 0.018052283 | N13: =D13+G13+K13 -> 0.5986292 | O13: =E13+H13+L13 -> 0.00025 | P13: =N13*1000/Fx+O13 -> 0.023120266 | Q13: =SUMIFS(#REF!,#REF!,'>>Chart'!C13) -> #REF! | R13: =SUMIFS(#REF!,#REF!,'>>Chart'!C13) -> #REF! | S13: =Q13/$Q$18 -> #REF!
C14: VIB - HOI SO | D14: =SUMIFS('Cash Balance'!$L$4:$L$920,'Cash Balance'!$Y$4:$Y$920,'>>Chart'!$C14,'Cash Balance'!$W$4:$W$920,'>>Chart'!D$1)/1000000000 -> 0.013672907 | E14: =SUMIFS('Cash Balance'!$T$4:$T$920,'Cash Balance'!$Y$4:$Y$920,'>>Chart'!$C14,'Cash Balance'!$W$4:$W$920,'>>Chart'!E$1)/1000000 -> 5.16e-05 | F14: =D14*1000/Fx+E14 -> 0.00057396512 | G14: =SUMIFS('Cash Balance'!$L$4:$L$920,'Cash Balance'!$Y$4:$Y$920,'>>Chart'!$C14,'Cash Balance'!$W$4:$W$920,'>>Chart'!G$1)/1000000000 -> 170.18762 | H14: =SUMIFS('Cash Balance'!$T$4:$T$920,'Cash Balance'!$Y$4:$Y$920,'>>Chart'!$C14,'Cash Balance'!$W$4:$W$920,'>>Chart'!H$1)/1000000 -> 0.0001 | I14: =G14/Fx*1000+H14 -> 6.5020148 | J14: =G14+H14*Fx/1000 -> 170.19024 | K14: =SUMIFS('Cash Balance'!$L$4:$L$920,'Cash Balance'!$Y$4:$Y$920,'>>Chart'!$C14,'Cash Balance'!$W$4:$W$920,'>>Chart'!K$1)/1000000000 -> 4.1944989 | L14: =SUMIFS('Cash Balance'!$T$4:$T$920,'Cash Balance'!$Y$4:$Y$920,'>>Chart'!$C14,'Cash Balance'!$W$4:$W$920,'>>Chart'!L$1)/1000000 -> 0 | M14: =K14*1000/Fx+L14 -> 0.16024829 | N14: =D14+G14+K14 -> 174.39579 | O14: =E14+H14+L14 -> 0.0001516 | P14: =N14*1000/Fx+O14 -> 6.662837 | Q14: =SUMIFS(#REF!,#REF!,'>>Chart'!C14) -> #REF! | R14: =SUMIFS(#REF!,#REF!,'>>Chart'!C14) -> #REF! | S14: =Q14/$Q$18 -> #REF!
C15: MB - BAC SAI GON | D15: =SUMIFS('Cash Balance'!$L$4:$L$920,'Cash Balance'!$Y$4:$Y$920,'>>Chart'!$C15,'Cash Balance'!$W$4:$W$920,'>>Chart'!D$1)/1000000000 -> 0 | E15: =SUMIFS('Cash Balance'!$T$4:$T$920,'Cash Balance'!$Y$4:$Y$920,'>>Chart'!$C15,'Cash Balance'!$W$4:$W$920,'>>Chart'!E$1)/1000000 -> 0 | F15: =D15*1000/Fx+E15 -> 0 | G15: =SUMIFS('Cash Balance'!$L$4:$L$920,'Cash Balance'!$Y$4:$Y$920,'>>Chart'!$C15,'Cash Balance'!$W$4:$W$920,'>>Chart'!G$1)/1000000000 -> 0.007958304 | H15: =SUMIFS('Cash Balance'!$T$4:$T$920,'Cash Balance'!$Y$4:$Y$920,'>>Chart'!$C15,'Cash Balance'!$W$4:$W$920,'>>Chart'!H$1)/1000000 -> 9e-05 | I15: =G15/Fx*1000+H15 -> 0.00039404218 | J15: =G15+H15*Fx/1000 -> 0.010314054 | K15: =SUMIFS('Cash Balance'!$L$4:$L$920,'Cash Balance'!$Y$4:$Y$920,'>>Chart'!$C15,'Cash Balance'!$W$4:$W$920,'>>Chart'!K$1)/1000000000 -> 0 | L15: =SUMIFS('Cash Balance'!$T$4:$T$920,'Cash Balance'!$Y$4:$Y$920,'>>Chart'!$C15,'Cash Balance'!$W$4:$W$920,'>>Chart'!L$1)/1000000 -> 0 | M15: =K15*1000/Fx+L15 -> 0 | N15: =D15+G15+K15 -> 0.007958304 | O15: =E15+H15+L15 -> 9e-05 | P15: =N15*1000/Fx+O15 -> 0.00039404218 | Q15: =SUMIFS(#REF!,#REF!,'>>Chart'!C15) -> #REF! | R15: =SUMIFS(#REF!,#REF!,'>>Chart'!C15) -> #REF! | S15: =Q15/$Q$18 -> #REF!
C16: SINOPAC | D16: =SUMIFS('Cash Balance'!$L$4:$L$920,'Cash Balance'!$Y$4:$Y$920,'>>Chart'!$C16,'Cash Balance'!$W$4:$W$920,'>>Chart'!D$1)/1000000000 -> 30.613469 | E16: =SUMIFS('Cash Balance'!$T$4:$T$920,'Cash Balance'!$Y$4:$Y$920,'>>Chart'!$C16,'Cash Balance'!$W$4:$W$920,'>>Chart'!E$1)/1000000 -> 0.01311974 | F16: =D16*1000/Fx+E16 -> 1.1826887 | G16: =SUMIFS('Cash Balance'!$L$4:$L$920,'Cash Balance'!$Y$4:$Y$920,'>>Chart'!$C16,'Cash Balance'!$W$4:$W$920,'>>Chart'!G$1)/1000000000 -> 40.074819 | H16: =SUMIFS('Cash Balance'!$T$4:$T$920,'Cash Balance'!$Y$4:$Y$920,'>>Chart'!$C16,'Cash Balance'!$W$4:$W$920,'>>Chart'!H$1)/1000000 -> 0 | I16: =G16/Fx*1000+H16 -> 1.5310342 | J16: =G16+H16*Fx/1000 -> 40.074819 | K16: =SUMIFS('Cash Balance'!$L$4:$L$920,'Cash Balance'!$Y$4:$Y$920,'>>Chart'!$C16,'Cash Balance'!$W$4:$W$920,'>>Chart'!K$1)/1000000000 -> 69.120993 | L16: =SUMIFS('Cash Balance'!$T$4:$T$920,'Cash Balance'!$Y$4:$Y$920,'>>Chart'!$C16,'Cash Balance'!$W$4:$W$920,'>>Chart'!L$1)/1000000 -> 0 | M16: =K16*1000/Fx+L16 -> 2.6407256 | N16: =D16+G16+K16 -> 139.80928 | O16: =E16+H16+L16 -> 0.01311974 | P16: =N16*1000/Fx+O16 -> 5.3544485 | Q16: =SUMIFS(#REF!,#REF!,'>>Chart'!C16) -> #REF! | R16: =SUMIFS(#REF!,#REF!,'>>Chart'!C16) -> #REF!
C17: OTHERS | D17: =SUMIFS('Cash Balance'!$L$4:$L$920,'Cash Balance'!$Y$4:$Y$920,'>>Chart'!$C17,'Cash Balance'!$W$4:$W$920,'>>Chart'!D$1)/1000000000 -> 0.18018878 | E17: =SUMIFS('Cash Balance'!$T$4:$T$920,'Cash Balance'!$Y$4:$Y$920,'>>Chart'!$C17,'Cash Balance'!$W$4:$W$920,'>>Chart'!E$1)/1000000 -> 3e-08 | F17: =D17*1000/Fx+E17 -> 0.0068840332 | G17: =SUMIFS('Cash Balance'!$L$4:$L$920,'Cash Balance'!$Y$4:$Y$920,'>>Chart'!$C17,'Cash Balance'!$W$4:$W$920,'>>Chart'!G$1)/1000000000 -> 0.64734746 | H17: =SUMIFS('Cash Balance'!$T$4:$T$920,'Cash Balance'!$Y$4:$Y$920,'>>Chart'!$C17,'Cash Balance'!$W$4:$W$920,'>>Chart'!H$1)/1000000 -> 0 | I17: =G17/Fx*1000+H17 -> 0.024731517 | J17: =G17+H17*Fx/1000 -> 0.64734746 | K17: =SUMIFS('Cash Balance'!$L$4:$L$920,'Cash Balance'!$Y$4:$Y$920,'>>Chart'!$C17,'Cash Balance'!$W$4:$W$920,'>>Chart'!K$1)/1000000000 -> 219.91921 | L17: =SUMIFS('Cash Balance'!$T$4:$T$920,'Cash Balance'!$Y$4:$Y$920,'>>Chart'!$C17,'Cash Balance'!$W$4:$W$920,'>>Chart'!L$1)/1000000 -> 0 | M17: =K17*1000/Fx+L17 -> 8.4018801 | N17: =D17+G17+K17 -> 220.74675 | O17: =E17+H17+L17 -> 3e-08 | P17: =N17*1000/Fx+O17 -> 8.4334957 | Q17: =SUMIFS(#REF!,#REF!,'>>Chart'!C17) -> #REF! | R17: =SUMIFS(#REF!,#REF!,'>>Chart'!C17) -> #REF! | S17: =Q17/$Q$18 -> #REF!
C18: TOTAL | D18: =SUM(D4:D17) -> 38.719551 | E18: =SUM(E4:E17) -> 0.01851847 | F18: =SUM(F4:F17) -> 1.4977754 | G18: =SUM(G4:G17) -> 1858.5591 | H18: =SUM(H4:H17) -> 0.00399282 | I18: =SUM(I4:I17) -> 71.009117 | J18: =SUM(J4:J17) -> 1858.6636 | K18: =SUM(K4:K17) -> 2084.9901 | ... M18: =SUM(M4:M17) -> 79.692348 | N18: =D18+G18+K18 -> 3982.2688 | O18: =E18+H18+L18 -> 0.05907661 | P18: =N18*1000/Fx+O18 -> 152.19924 | Q18: =SUM(Q4:Q17) -> #REF! | R18: =SUM(R4:R17) -> #REF! | S18: =Q18/$Q$18 -> #REF!
C21: Row Labels | D21: Sum of BW_Total_USD_mn | E21: Sum of VC3_Total_USD_mn | F21: Sum of SUB_TOTAL_USD_mn | G21: Sum of Total
C22: BIDV - LONG BIEN | D22: 0 | E22: 0 | F22: 1.2728541 | G22: 1.2728541
C23: BIDV - NAM SAI GON | D23: 0 | E23: 0 | F23: 3.0989018 | G23: 3.0989018
C24: BIDV - THANH XUAN | D24: 0.0015521126 | E24: 1.9329444 | F24: 12.531195 | G24: 14.465691
C25: MB - BAC SAI GON | D25: 0 | E25: 0.00039601238 | F25: 0 | G25: 0.00039601238
C26: OCB - BINH DUONG | D26: 0.0028399669 | E26: 0.0022845483 | F26: 0.052526566 | G26: 0.057651081
C27: OTHERS | D27: 0.0069283002 | E27: 0.016659581 | F27: 3.3959035 | G27: 3.4194914
C28: SINOPAC | D28: 1.1683116 | E28: 1.945968 | F28: 2.8833237 | G28: 5.9976034
C29: VIB - HOI SO | D29: 0.00058975969 | E29: 6.5457686 | F29: 0.12115174 | G29: 6.6675101
C30: VIETCOMBANK - BA DINH | D30: 0.017156796 | E30: 0.078774524 | F30: 5.2258423 | G30: 5.3217736
C31: VIETCOMBANK - HCM | D31: 0.011771033 | E31: 44.040424 | F31: 3.872738 | G31: 47.924933
C32: VIETINBANK - BINH DUONG + QM | D32: 0.50274374 | E32: 7.0234828 | F32: 8.9906742 | G32: 16.516901
C33: VIETINBANK - CN1 | D33: 0.004238503 | E33: 0.0071696772 | F33: 3.4427433 | G33: 3.4541514
... C36: Grand Total | D36: 1.7182163 | E36: 64.181634 | F36: 67.113845 | G36: 133.0137
D42: =ROUND(SUM(F4:F17),0)=ROUND(SUM(D45:D61),0) -> TRUE | E42: =ROUND(SUM(I4:I17),0)=ROUND(SUM(E45:E61),0) -> TRUE | F42: =ROUND(SUM(M4:M17),0)=ROUND(SUM(F45:F61),0) -> TRUE | G42: =ROUND(SUM(P4:P17),0)=ROUND(SUM(G45:G61),0) -> TRUE
R43: Bank
C44: Bank | D44: BW | E44: VC3 | F44: Subs | G44: Total | H44: FA | J44: % | K44: %/FA | N44: % | R44: VTB | S44: =SUMIFS($G$45:$G$61,$A$45:$A$61,'>>Chart'!R44)/'>>Chart'!$P$18 -> 0.37925032
A45: VTB | B45: VTB TS | C45: VIETINBANK - TIEN SON | D45: =_xlfn.XLOOKUP($C45,$C$4:$C$17,$F$4:$F$17,0,0,1) -> 0.0013094371 | E45: =_xlfn.XLOOKUP($C45,$C$4:$C$17,$I$4:$I$17,0,0,1) -> 9.9968845 | F45: =_xlfn.XLOOKUP($C45,$C$4:$C$17,$M$4:$M$17,0,0,1) -> 20.61079 | G45: =SUM(D45:F45) -> 30.608983 | H45: =_xlfn.XLOOKUP($C45,$C$4:$C$17,$Q$4:$Q$17,0,0,1) -> #REF! | J45: =G45/SUM($G$45:$G$61) -> 0.20111128 | K45: =IFERROR(H45/SUM($H$45:$H$61),0) -> 0 | N45: =J45 -> 0.20111128 | R45: VCB | S45: =SUMIFS($G$45:$G$61,$A$45:$A$61,'>>Chart'!R45)/'>>Chart'!$P$18 -> 0.39185647
A46: VTB | B46: VTB BD + QM | C46: VIETINBANK - BINH DUONG + QM | D46: =_xlfn.XLOOKUP($C46,$C$4:$C$17,$F$4:$F$17,0,0,1) -> 0.26810015 | E46: =_xlfn.XLOOKUP($C46,$C$4:$C$17,$I$4:$I$17,0,0,1) -> 4.2206393 | F46: =_xlfn.XLOOKUP($C46,$C$4:$C$17,$M$4:$M$17,0,0,1) -> 16.326178 | G46: =SUM(D46:F46) -> 20.814917 | H46: =_xlfn.XLOOKUP($C46,$C$4:$C$17,$Q$4:$Q$17,0,0,1) -> #REF! | J46: =G46/SUM($G$45:$G$61) -> 0.13676098 | K46: =IFERROR(H46/SUM($H$45:$H$61),0) -> 0 | N46: =J46 -> 0.13676098 | R46: BIDV | S46: =SUMIFS($G$45:$G$61,$A$45:$A$61,'>>Chart'!R46)/'>>Chart'!$P$18 -> 0.094370229
A47: VTB | B47: VTB DSG | C47: VIETINBANK - DONG SAI GON | D47: =_xlfn.XLOOKUP($C47,$C$4:$C$17,$F$4:$F$17,0,0,1) -> 0.000769 | E47: =_xlfn.XLOOKUP($C47,$C$4:$C$17,$I$4:$I$17,0,0,1) -> 0.00015646415 | F47: =_xlfn.XLOOKUP($C47,$C$4:$C$17,$M$4:$M$17,0,0,1) -> 4.0462508 | G47: =SUM(D47:F47) -> 4.0471763 | H47: =_xlfn.XLOOKUP($C47,$C$4:$C$17,$Q$4:$Q$17,0,0,1) -> #REF! | J47: =G47/SUM($G$45:$G$61) -> 0.026591304 | K47: =IFERROR(H47/SUM($H$45:$H$61),0) -> 0 | N47: =J47 -> 0.026591304 | R47: OCB | S47: =SUMIFS($G$45:$G$61,$A$45:$A$61,'>>Chart'!R47)/'>>Chart'!$P$18 -> 0.00015190789
A48: VTB | B48: VTB CN1 | C48: VIETINBANK - CN1 | D48: =_xlfn.XLOOKUP($C48,$C$4:$C$17,$F$4:$F$17,0,0,1) -> 0.0042198677 | E48: =_xlfn.XLOOKUP($C48,$C$4:$C$17,$I$4:$I$17,0,0,1) -> 0.0071336651 | F48: =_xlfn.XLOOKUP($C48,$C$4:$C$17,$M$4:$M$17,0,0,1) -> 2.2391806 | G48: =SUM(D48:F48) -> 2.2505342 | H48: =_xlfn.XLOOKUP($C48,$C$4:$C$17,$Q$4:$Q$17,0,0,1) -> #REF! | J48: =G48/SUM($G$45:$G$61) -> 0.014786763 | K48: =IFERROR(H48/SUM($H$45:$H$61),0) -> 0 | N48: =J48 -> 0.014786763 | R48: VIB | S48: =SUMIFS($G$45:$G$61,$A$45:$A$61,'>>Chart'!R48)/'>>Chart'!$P$18 -> 0.043777072
D49: =_xlfn.XLOOKUP($C49,$C$4:$C$17,$F$4:$F$17,0,0,1) -> 0 | E49: =_xlfn.XLOOKUP($C49,$C$4:$C$17,$I$4:$I$17,0,0,1) -> 0 | F49: =_xlfn.XLOOKUP($C49,$C$4:$C$17,$M$4:$M$17,0,0,1) -> 0 | H49: =_xlfn.XLOOKUP($C49,$C$4:$C$17,$Q$4:$Q$17,0,0,1) -> 0 | L49: =SUM(G45:G48) -> 57.721611 | R49: MBB | S49: =SUMIFS($G$45:$G$61,$A$45:$A$61,'>>Chart'!R49)/'>>Chart'!$P$18 -> 2.5889891e-06
...

Sheet Sheet5
A1: Grouping | B1: Subsidiaries
A3: Row Labels | B3: Sum of Net
A4: Internal transfer in | B4: 8200000000 | D4: =B4/24000/10^6 -> 0.34166667
A5: Other receipts | B5: 738950017 | D5: =B5/24000/10^6 -> 0.030789584
A6: Receipt from tenants | B6: 15707326732 | D6: =B6/24000/10^6 -> 0.65447195
A7: Grand Total | B7: 24646276749 | D7: =B7/24000/10^6 -> 1.0269282
D8: =B8/24000/10^6 -> 0
D9: =B9/24000/10^6 -> 0
D10: =B10/24000/10^6 -> 0
D11: =B11/24000/10^6 -> 0
D12: =B12/24000/10^6 -> 0 | E12: ok

Sheet Summary
A1: Date | B1: 46037
A2: Ver | B2: 1
A3: FX rate (VND/USD) | B3: 26175
A4: Week | B4: W1-2Jan26
A5: Opening date | B5: 46023
A6: Ending date | B6: 46037
A8: ="1. Outstanding cash @ "&TEXT(B6,"dd/mm/yyyy") -> 1. Outstanding cash @ 15/01/2026
A10: ="Total cash ending balance of BWID Group was US"&TEXT($D$18,"$#,###.00")&"mn equivalent, in which US"&TEXT(D15,"$#,###.00")&"mn at BWID JSC ("&TEXT($D$15/$D$18,"#.00%")&"), US"&TEXT($D$16,"$#,###.00")&"mn at VC3 ("&TEXT($D$16/$D$18,"#.00%")&"), and US"&TEXT(D17,"$#,###.00")&"mn at Subsidiaries ("&TEXT($D$17/$D$18,"#.00%")&")" -> Total cash ending balance of BWID Group was US$162,14618mn equivalent, in which US$1,50415mn at BWID JSC (01%), US$71,64870mn at VC3 (44%), and US$88,99333mn at Subsidiaries (55%)
A11: ="Total cash of BWID group from "&TEXT($B$5,"dd-mmm-yy")&" to "&TEXT($B$6,"dd-mmm-yy")&" "&IF($E$78+$E$94>0,"increased",IF($E$78+$E$94=0,"remained unchange","decreased"))&" by "&TEXT(ABS($E$78+$E$94),"$##0.0")&"mn ("&TEXT(($E$78+$E$94)/$E$77,"#0.00%")&")" -> Total cash of BWID group from 01-Jan-26 to 15-Jan-26 increased by $28mn (021%)
A13: Entity | B13: Cash in original VND | C13: Cash in original USD | D13: Total cash
B14: in USDmn equivalent | C14: in USDmn | D14: in USDmn equivalent | F14: Cash in original VND
A15: BWID JSC | B15: =SUMIFS('Cash Balance'!$L$4:$L$920,'Cash Balance'!$W$4:$W$920,Summary!$A15)/1000000/Fx_rate -> 1.4846825 | C15: =SUMIFS('Cash Balance'!$T$4:$T$920,'Cash Balance'!$W$4:$W$920,Summary!$A15)/1000000 -> 0.01946847 | D15: =B15+C15 -> 1.504151 | F15: =SUMIFS('Cash Balance'!$L$4:$L$920,'Cash Balance'!$W$4:$W$920,Summary!$A15) -> 38861564578
A16: VC3 | B16: =SUMIFS('Cash Balance'!$L$4:$L$920,'Cash Balance'!$W$4:$W$920,Summary!$A16)/1000000/Fx_rate -> 71.63907 | C16: =SUMIFS('Cash Balance'!$T$4:$T$920,'Cash Balance'!$W$4:$W$920,Summary!$A16)/1000000 -> 0.00962906 | D16: =B16+C16 -> 71.648699 | F16: =SUMIFS('Cash Balance'!$L$4:$L$920,'Cash Balance'!$W$4:$W$920,Summary!$A16) -> 1875152665621
A17: Subsidiaries | B17: =SUMIFS('Cash Balance'!$L$4:$L$920,'Cash Balance'!$W$4:$W$920,Summary!$A17)/1000000/Fx_rate -> 88.956757 | C17: =SUMIFS('Cash Balance'!$T$4:$T$920,'Cash Balance'!$W$4:$W$920,Summary!$A17)/1000000 -> 0.03657006 | D17: =B17+C17 -> 88.993328 | F17: =SUMIFS('Cash Balance'!$L$4:$L$920,'Cash Balance'!$W$4:$W$920,Summary!$A17) -> 2328443126281
A18: Total | B18: =SUM(B15:B17) -> 162.08051 | C18: =SUM(C15:C17) -> 0.06566759 | D18: =SUM(D15:D17) -> 162.14618 | F18: =SUM(F15:F17) -> 4242457356480
A30: ="In which, BWID Group's cash is mainly at VIETINBANK: US"&TEXT(E34,"$#,###.00")&"mn ("&TEXT(F34,"#.00%")&") , VIETCOMBANK: USD"&TEXT(E42,"$#,###.00")&"mn ("&TEXT(F42,"#.00%")&"), and BIDV: USD"&TEXT(E47,"$#,###.00")&"mn ("&TEXT(F47,"#.00%")&")" -> In which, BWID Group's cash is mainly at VIETINBANK: US$63,76119mn (39%) , VIETCOMBANK: USD$59,64026mn (37%), and BIDV: USD$14,36308mn (09%)
B32: BWID JSC | C32: VC3 | D32: Subsidiaries | E32: Total | F32: %
B33: in USDmn equivalent | C33: in USDmn equivalent | D33: in USDmn equivalent | E33: in USDmn equivalent
A34: VIETINBANK | B34: =SUBTOTAL(9,B35:B41) -> 0.27439845 | C34: =SUBTOTAL(9,C35:C41) -> 14.281298 | D34: =SUBTOTAL(9,D35:D41) -> 49.205493 | E34: =SUBTOTAL(9,E35:E41) -> 63.76119 | F34: =SUBTOTAL(9,F35:F41) -> 0.39323276
A35: VIETINBANK - TIEN SON | B35: =SUMIFS('Cash Balance'!$L$4:$L$920,'Cash Balance'!$W$4:$W$920,Summary!B$32,'Cash Balance'!$Y$4:$Y$920,Summary!$A35)/Fx_rate/1000000+SUMIFS('Cash Balance'!$T$4:$T$920,'Cash Balance'!$W$4:$W$920,Summary!B$32,'Cash Balance'!$Y$4:$Y$920,Summary!$A35)/1000000 -> 0.0013094371 | C35: =SUMIFS('Cash Balance'!$L$4:$L$920,'Cash Balance'!$W$4:$W$920,Summary!C$32,'Cash Balance'!$Y$4:$Y$920,Summary!$A35)/Fx_rate/1000000+SUMIFS('Cash Balance'!$T$4:$T$920,'Cash Balance'!$W$4:$W$920,Summary!C$32,'Cash Balance'!$Y$4:$Y$920,Summary!$A35)/1000000 -> 9.9968845 | D35: =SUMIFS('Cash Balance'!$L$4:$L$920,'Cash Balance'!$W$4:$W$920,Summary!D$32,'Cash Balance'!$Y$4:$Y$920,Summary!$A35)/Fx_rate/1000000+SUMIFS('Cash Balance'!$T$4:$T$920,'Cash Balance'!$W$4:$W$920,Summary!D$32,'Cash Balance'!$Y$4:$Y$920,Summary!$A35)/1000000 -> 20.61079 | E35: =SUM(B35:D35) -> 30.608983 | F35: =E35/$E$63 -> 0.18877401
A36: VIETINBANK - BINH DUONG + QM | B36: =SUMIFS('Cash Balance'!$L$4:$L$920,'Cash Balance'!$W$4:$W$920,Summary!B$32,'Cash Balance'!$Y$4:$Y$920,Summary!$A36)/Fx_rate/1000000+SUMIFS('Cash Balance'!$T$4:$T$920,'Cash Balance'!$W$4:$W$920,Summary!B$32,'Cash Balance'!$Y$4:$Y$920,Summary!$A36)/1000000 -> 0.26810015 | C36: =SUMIFS('Cash Balance'!$L$4:$L$920,'Cash Balance'!$W$4:$W$920,Summary!C$32,'Cash Balance'!$Y$4:$Y$920,Summary!$A36)/Fx_rate/1000000+SUMIFS('Cash Balance'!$T$4:$T$920,'Cash Balance'!$W$4:$W$920,Summary!C$32,'Cash Balance'!$Y$4:$Y$920,Summary!$A36)/1000000 -> 4.2206393 | D36: =SUMIFS('Cash Balance'!$L$4:$L$920,'Cash Balance'!$W$4:$W$920,Summary!D$32,'Cash Balance'!$Y$4:$Y$920,Summary!$A36)/Fx_rate/1000000+SUMIFS('Cash Balance'!$T$4:$T$920,'Cash Balance'!$W$4:$W$920,Summary!D$32,'Cash Balance'!$Y$4:$Y$920,Summary!$A36)/1000000 -> 16.326178 | E36: =SUM(B36:D36) -> 20.814917 | F36: =E36/$E$63 -> 0.12837131
A37: VIETINBANK - DONG SAI GON | B37: =SUMIFS('Cash Balance'!$L$4:$L$920,'Cash Balance'!$W$4:$W$920,Summary!B$32,'Cash Balance'!$Y$4:$Y$920,Summary!$A37)/Fx_rate/1000000+SUMIFS('Cash Balance'!$T$4:$T$920,'Cash Balance'!$W$4:$W$920,Summary!B$32,'Cash Balance'!$Y$4:$Y$920,Summary!$A37)/1000000 -> 0.000769 | C37: =SUMIFS('Cash Balance'!$L$4:$L$920,'Cash Balance'!$W$4:$W$920,Summary!C$32,'Cash Balance'!$Y$4:$Y$920,Summary!$A37)/Fx_rate/1000000+SUMIFS('Cash Balance'!$T$4:$T$920,'Cash Balance'!$W$4:$W$920,Summary!C$32,'Cash Balance'!$Y$4:$Y$920,Summary!$A37)/1000000 -> 0.00015646415 | D37: =SUMIFS('Cash Balance'!$L$4:$L$920,'Cash Balance'!$W$4:$W$920,Summary!D$32,'Cash Balance'!$Y$4:$Y$920,Summary!$A37)/Fx_rate/1000000+SUMIFS('Cash Balance'!$T$4:$T$920,'Cash Balance'!$W$4:$W$920,Summary!D$32,'Cash Balance'!$Y$4:$Y$920,Summary!$A37)/1000000 -> 4.0462508 | E37: =SUM(B37:D37) -> 4.0471763 | F37: =E37/$E$63 -> 0.024960048
A38: VIETINBANK - CN1 | B38: =SUMIFS('Cash Balance'!$L$4:$L$920,'Cash Balance'!$W$4:$W$920,Summary!B$32,'Cash Balance'!$Y$4:$Y$920,Summary!$A38)/Fx_rate/1000000+SUMIFS('Cash Balance'!$T$4:$T$920,'Cash Balance'!$W$4:$W$920,Summary!B$32,'Cash Balance'!$Y$4:$Y$920,Summary!$A38)/1000000 -> 0.0042198677 | C38: =SUMIFS('Cash Balance'!$L$4:$L$920,'Cash Balance'!$W$4:$W$920,Summary!C$32,'Cash Balance'!$Y$4:$Y$920,Summary!$A38)/Fx_rate/1000000+SUMIFS('Cash Balance'!$T$4:$T$920,'Cash Balance'!$W$4:$W$920,Summary!C$32,'Cash Balance'!$Y$4:$Y$920,Summary!$A38)/1000000 -> 0.0071336651 | D38: =SUMIFS('Cash Balance'!$L$4:$L$920,'Cash Balance'!$W$4:$W$920,Summary!D$32,'Cash Balance'!$Y$4:$Y$920,Summary!$A38)/Fx_rate/1000000+SUMIFS('Cash Balance'!$T$4:$T$920,'Cash Balance'!$W$4:$W$920,Summary!D$32,'Cash Balance'!$Y$4:$Y$920,Summary!$A38)/1000000 -> 2.2391806 | E38: =SUM(B38:D38) -> 2.2505342 | F38: =E38/$E$63 -> 0.013879662
A39: VIETINBANK - HA NOI | B39: =SUMIFS('Cash Balance'!$L$4:$L$920,'Cash Balance'!$W$4:$W$920,Summary!B$32,'Cash Balance'!$Y$4:$Y$920,Summary!$A39)/Fx_rate/1000000+SUMIFS('Cash Balance'!$T$4:$T$920,'Cash Balance'!$W$4:$W$920,Summary!B$32,'Cash Balance'!$Y$4:$Y$920,Summary!$A39)/1000000 -> 0 | C39: =SUMIFS('Cash Balance'!$L$4:$L$920,'Cash Balance'!$W$4:$W$920,Summary!C$32,'Cash Balance'!$Y$4:$Y$920,Summary!$A39)/Fx_rate/1000000+SUMIFS('Cash Balance'!$T$4:$T$920,'Cash Balance'!$W$4:$W$920,Summary!C$32,'Cash Balance'!$Y$4:$Y$920,Summary!$A39)/1000000 -> 0 | D39: =SUMIFS('Cash Balance'!$L$4:$L$920,'Cash Balance'!$W$4:$W$920,Summary!D$32,'Cash Balance'!$Y$4:$Y$920,Summary!$A39)/Fx_rate/1000000+SUMIFS('Cash Balance'!$T$4:$T$920,'Cash Balance'!$W$4:$W$920,Summary!D$32,'Cash Balance'!$Y$4:$Y$920,Summary!$A39)/1000000 -> 0 | E39: =SUM(B39:D39) -> 0 | F39: =E39/$E$63 -> 0
A40: VIETINBANK - TPHCM | B40: =SUMIFS('Cash Balance'!$L$4:$L$920,'Cash Balance'!$W$4:$W$920,Summary!B$32,'Cash Balance'!$Y$4:$Y$920,Summary!$A40)/Fx_rate/1000000+SUMIFS('Cash Balance'!$T$4:$T$920,'Cash Balance'!$W$4:$W$920,Summary!B$32,'Cash Balance'!$Y$4:$Y$920,Summary!$A40)/1000000 -> 0 | C40: =SUMIFS('Cash Balance'!$L$4:$L$920,'Cash Balance'!$W$4:$W$920,Summary!C$32,'Cash Balance'!$Y$4:$Y$920,Summary!$A40)/Fx_rate/1000000+SUMIFS('Cash Balance'!$T$4:$T$920,'Cash Balance'!$W$4:$W$920,Summary!C$32,'Cash Balance'!$Y$4:$Y$920,Summary!$A40)/1000000 -> 0.05648412 | D40: =SUMIFS('Cash Balance'!$L$4:$L$920,'Cash Balance'!$W$4:$W$920,Summary!D$32,'Cash Balance'!$Y$4:$Y$920,Summary!$A40)/Fx_rate/1000000+SUMIFS('Cash Balance'!$T$4:$T$920,'Cash Balance'!$W$4:$W$920,Summary!D$32,'Cash Balance'!$Y$4:$Y$920,Summary!$A40)/1000000 -> 5.9830946 | E40: =SUM(B40:D40) -> 6.0395787 | F40: =E40/$E$63 -> 0.03724774
A41: VIETINBANK - CN6 | B41: =SUMIFS('Cash Balance'!$L$4:$L$920,'Cash Balance'!$W$4:$W$920,Summary!B$32,'Cash Balance'!$Y$4:$Y$920,Summary!$A41)/Fx_rate/1000000+SUMIFS('Cash Balance'!$T$4:$T$920,'Cash Balance'!$W$4:$W$920,Summary!B$32,'Cash Balance'!$Y$4:$Y$920,Summary!$A41)/1000000 -> 0 | C41: =SUMIFS('Cash Balance'!$L$4:$L$920,'Cash Balance'!$W$4:$W$920,Summary!C$32,'Cash Balance'!$Y$4:$Y$920,Summary!$A41)/Fx_rate/1000000+SUMIFS('Cash Balance'!$T$4:$T$920,'Cash Balance'!$W$4:$W$920,Summary!C$32,'Cash Balance'!$Y$4:$Y$920,Summary!$A41)/1000000 -> 0 | D41: =SUMIFS('Cash Balance'!$L$4:$L$920,'Cash Balance'!$W$4:$W$920,Summary!D$32,'Cash Balance'!$Y$4:$Y$920,Summary!$A41)/Fx_rate/1000000+SUMIFS('Cash Balance'!$T$4:$T$920,'Cash Balance'!$W$4:$W$920,Summary!D$32,'Cash Balance'!$Y$4:$Y$920,Summary!$A41)/1000000 -> 0 | E41: =SUM(B41:D41) -> 0 | F41: =E41/$E$63 -> 0
A42: VIETCOMBANK | B42: =SUBTOTAL(9,B43:B44) -> 0.028901303 | C42: =SUBTOTAL(9,C43:C44) -> 48.515364 | D42: =SUBTOTAL(9,D43:D44) -> 11.095992 | E42: =SUBTOTAL(9,E43:E44) -> 59.640257 | F42: =SUBTOTAL(9,F43:F44) -> 0.36781784
A43: VIETCOMBANK - HCM | B43: =SUMIFS('Cash Balance'!$L$4:$L$920,'Cash Balance'!$W$4:$W$920,Summary!B$32,'Cash Balance'!$Y$4:$Y$920,Summary!$A43)/Fx_rate/1000000+SUMIFS('Cash Balance'!$T$4:$T$920,'Cash Balance'!$W$4:$W$920,Summary!B$32,'Cash Balance'!$Y$4:$Y$920,Summary!$A43)/1000000 -> 0.011851238 | C43: =SUMIFS('Cash Balance'!$L$4:$L$920,'Cash Balance'!$W$4:$W$920,Summary!C$32,'Cash Balance'!$Y$4:$Y$920,Summary!$A43)/Fx_rate/1000000+SUMIFS('Cash Balance'!$T$4:$T$920,'Cash Balance'!$W$4:$W$920,Summary!C$32,'Cash Balance'!$Y$4:$Y$920,Summary!$A43)/1000000 -> 48.437015 | D43: =SUMIFS('Cash Balance'!$L$4:$L$920,'Cash Balance'!$W$4:$W$920,Summary!D$32,'Cash Balance'!$Y$4:$Y$920,Summary!$A43)/Fx_rate/1000000+SUMIFS('Cash Balance'!$T$4:$T$920,'Cash Balance'!$W$4:$W$920,Summary!D$32,'Cash Balance'!$Y$4:$Y$920,Summary!$A43)/1000000 -> 6.548025 | E43: =SUM(B43:D43) -> 54.996891 | F43: =E43/$E$63 -> 0.33918093
A44: VIETCOMBANK - BA DINH | B44: =SUMIFS('Cash Balance'!$L$4:$L$920,'Cash Balance'!$W$4:$W$920,Summary!B$32,'Cash Balance'!$Y$4:$Y$920,Summary!$A44)/Fx_rate/1000000+SUMIFS('Cash Balance'!$T$4:$T$920,'Cash Balance'!$W$4:$W$920,Summary!B$32,'Cash Balance'!$Y$4:$Y$920,Summary!$A44)/1000000 -> 0.017050065 | C44: =SUMIFS('Cash Balance'!$L$4:$L$920,'Cash Balance'!$W$4:$W$920,Summary!C$32,'Cash Balance'!$Y$4:$Y$920,Summary!$A44)/Fx_rate/1000000+SUMIFS('Cash Balance'!$T$4:$T$920,'Cash Balance'!$W$4:$W$920,Summary!C$32,'Cash Balance'!$Y$4:$Y$920,Summary!$A44)/1000000 -> 0.078349322 | D44: =SUMIFS('Cash Balance'!$L$4:$L$920,'Cash Balance'!$W$4:$W$920,Summary!D$32,'Cash Balance'!$Y$4:$Y$920,Summary!$A44)/Fx_rate/1000000+SUMIFS('Cash Balance'!$T$4:$T$920,'Cash Balance'!$W$4:$W$920,Summary!D$32,'Cash Balance'!$Y$4:$Y$920,Summary!$A44)/1000000 -> 4.5479666 | E44: =SUM(B44:D44) -> 4.643366 | F44: =E44/$E$63 -> 0.028636913
A45: VIETCOMBANK - NAM BINH DUONG | B45: =SUMIFS('Cash Balance'!$L$4:$L$920,'Cash Balance'!$W$4:$W$920,Summary!B$32,'Cash Balance'!$Y$4:$Y$920,Summary!$A45)/Fx_rate/1000000+SUMIFS('Cash Balance'!$T$4:$T$920,'Cash Balance'!$W$4:$W$920,Summary!B$32,'Cash Balance'!$Y$4:$Y$920,Summary!$A45)/1000000 -> 0 | C45: =SUMIFS('Cash Balance'!$L$4:$L$920,'Cash Balance'!$W$4:$W$920,Summary!C$32,'Cash Balance'!$Y$4:$Y$920,Summary!$A45)/Fx_rate/1000000+SUMIFS('Cash Balance'!$T$4:$T$920,'Cash Balance'!$W$4:$W$920,Summary!C$32,'Cash Balance'!$Y$4:$Y$920,Summary!$A45)/1000000 -> 0 | D45: =SUMIFS('Cash Balance'!$L$4:$L$920,'Cash Balance'!$W$4:$W$920,Summary!D$32,'Cash Balance'!$Y$4:$Y$920,Summary!$A45)/Fx_rate/1000000+SUMIFS('Cash Balance'!$T$4:$T$920,'Cash Balance'!$W$4:$W$920,Summary!D$32,'Cash Balance'!$Y$4:$Y$920,Summary!$A45)/1000000 -> 0.00031520745 | E45: =SUM(B45:D45) -> 0.00031520745 | F45: =E45/$E$63 -> 1.9439709e-06
A46: VIETCOMBANK - BINH TAY | B46: =SUMIFS('Cash Balance'!$L$4:$L$920,'Cash Balance'!$W$4:$W$920,Summary!B$32,'Cash Balance'!$Y$4:$Y$920,Summary!$A46)/Fx_rate/1000000+SUMIFS('Cash Balance'!$T$4:$T$920,'Cash Balance'!$W$4:$W$920,Summary!B$32,'Cash Balance'!$Y$4:$Y$920,Summary!$A46)/1000000 -> 0 | C46: =SUMIFS('Cash Balance'!$L$4:$L$920,'Cash Balance'!$W$4:$W$920,Summary!C$32,'Cash Balance'!$Y$4:$Y$920,Summary!$A46)/Fx_rate/1000000+SUMIFS('Cash Balance'!$T$4:$T$920,'Cash Balance'!$W$4:$W$920,Summary!C$32,'Cash Balance'!$Y$4:$Y$920,Summary!$A46)/1000000 -> 0 | D46: =SUMIFS('Cash Balance'!$L$4:$L$920,'Cash Balance'!$W$4:$W$920,Summary!D$32,'Cash Balance'!$Y$4:$Y$920,Summary!$A46)/Fx_rate/1000000+SUMIFS('Cash Balance'!$T$4:$T$920,'Cash Balance'!$W$4:$W$920,Summary!D$32,'Cash Balance'!$Y$4:$Y$920,Summary!$A46)/1000000 -> 7.1023075e-05 | E46: =SUM(B46:D46) -> 7.1023075e-05 | F46: =E46/$E$63 -> 4.3801881e-07
A47: BIDV | B47: =SUBTOTAL(9,B48:B51) -> 0.0015188622 | C47: =SUBTOTAL(9,C48:C51) -> 0.20850692 | D47: =SUBTOTAL(9,D48:D51) -> 14.153051 | E47: =SUBTOTAL(9,E48:E50) -> 14.363077 | F47: =SUBTOTAL(9,F48:F50) -> 0.08858104
A48: BIDV - THANH XUAN | B48: =SUMIFS('Cash Balance'!$L$4:$L$920,'Cash Balance'!$W$4:$W$920,Summary!B$32,'Cash Balance'!$Y$4:$Y$920,Summary!$A48)/Fx_rate/1000000+SUMIFS('Cash Balance'!$T$4:$T$920,'Cash Balance'!$W$4:$W$920,Summary!B$32,'Cash Balance'!$Y$4:$Y$920,Summary!$A48)/1000000 -> 0.0015188622 | C48: =SUMIFS('Cash Balance'!$L$4:$L$920,'Cash Balance'!$W$4:$W$920,Summary!C$32,'Cash Balance'!$Y$4:$Y$920,Summary!$A48)/Fx_rate/1000000+SUMIFS('Cash Balance'!$T$4:$T$920,'Cash Balance'!$W$4:$W$920,Summary!C$32,'Cash Balance'!$Y$4:$Y$920,Summary!$A48)/1000000 -> 0.20850692 | D48: =SUMIFS('Cash Balance'!$L$4:$L$920,'Cash Balance'!$W$4:$W$920,Summary!D$32,'Cash Balance'!$Y$4:$Y$920,Summary!$A48)/Fx_rate/1000000+SUMIFS('Cash Balance'!$T$4:$T$920,'Cash Balance'!$W$4:$W$920,Summary!D$32,'Cash Balance'!$Y$4:$Y$920,Summary!$A48)/1000000 -> 11.010221 | E48: =SUM(B48:D48) -> 11.220247 | F48: =E48/$E$63 -> 0.069198341
A49: BIDV - NAM SAI GON | B49: =SUMIFS('Cash Balance'!$L$4:$L$920,'Cash Balance'!$W$4:$W$920,Summary!B$32,'Cash Balance'!$Y$4:$Y$920,Summary!$A49)/Fx_rate/1000000+SUMIFS('Cash Balance'!$T$4:$T$920,'Cash Balance'!$W$4:$W$920,Summary!B$32,'Cash Balance'!$Y$4:$Y$920,Summary!$A49)/1000000 -> 0 | C49: =SUMIFS('Cash Balance'!$L$4:$L$920,'Cash Balance'!$W$4:$W$920,Summary!C$32,'Cash Balance'!$Y$4:$Y$920,Summary!$A49)/Fx_rate/1000000+SUMIFS('Cash Balance'!$T$4:$T$920,'Cash Balance'!$W$4:$W$920,Summary!C$32,'Cash Balance'!$Y$4:$Y$920,Summary!$A49)/1000000 -> 0 | D49: =SUMIFS('Cash Balance'!$L$4:$L$920,'Cash Balance'!$W$4:$W$920,Summary!D$32,'Cash Balance'!$Y$4:$Y$920,Summary!$A49)/Fx_rate/1000000+SUMIFS('Cash Balance'!$T$4:$T$920,'Cash Balance'!$W$4:$W$920,Summary!D$32,'Cash Balance'!$Y$4:$Y$920,Summary!$A49)/1000000 -> 3.1388068 | E49: =SUM(B49:D49) -> 3.1388068 | F49: =E49/$E$63 -> 0.019357883
A50: BIDV - LONG BIEN | B50: =SUMIFS('Cash Balance'!$L$4:$L$920,'Cash Balance'!$W$4:$W$920,Summary!B$32,'Cash Balance'!$Y$4:$Y$920,Summary!$A50)/Fx_rate/1000000+SUMIFS('Cash Balance'!$T$4:$T$920,'Cash Balance'!$W$4:$W$920,Summary!B$32,'Cash Balance'!$Y$4:$Y$920,Summary!$A50)/1000000 -> 0 | C50: =SUMIFS('Cash Balance'!$L$4:$L$920,'Cash Balance'!$W$4:$W$920,Summary!C$32,'Cash Balance'!$Y$4:$Y$920,Summary!$A50)/Fx_rate/1000000+SUMIFS('Cash Balance'!$T$4:$T$920,'Cash Balance'!$W$4:$W$920,Summary!C$32,'Cash Balance'!$Y$4:$Y$920,Summary!$A50)/1000000 -> 0 | D50: =SUMIFS('Cash Balance'!$L$4:$L$920,'Cash Balance'!$W$4:$W$920,Summary!D$32,'Cash Balance'!$Y$4:$Y$920,Summary!$A50)/Fx_rate/1000000+SUMIFS('Cash Balance'!$T$4:$T$920,'Cash Balance'!$W$4:$W$920,Summary!D$32,'Cash Balance'!$Y$4:$Y$920,Summary!$A50)/1000000 -> 0.0040238321 | E50: =SUM(B50:D50) -> 0.0040238321 | F50: =E50/$E$63 -> 2.4816078e-05
A51: BIDV - GIA DINH | B51: =SUMIFS('Cash Balance'!$L$4:$L$920,'Cash Balance'!$W$4:$W$920,Summary!B$32,'Cash Balance'!$Y$4:$Y$920,Summary!$A51)/Fx_rate/1000000+SUMIFS('Cash Balance'!$T$4:$T$920,'Cash Balance'!$W$4:$W$920,Summary!B$32,'Cash Balance'!$Y$4:$Y$920,Summary!$A51)/1000000 -> 0 | C51: =SUMIFS('Cash Balance'!$L$4:$L$920,'Cash Balance'!$W$4:$W$920,Summary!C$32,'Cash Balance'!$Y$4:$Y$920,Summary!$A51)/Fx_rate/1000000+SUMIFS('Cash Balance'!$T$4:$T$920,'Cash Balance'!$W$4:$W$920,Summary!C$32,'Cash Balance'!$Y$4:$Y$920,Summary!$A51)/1000000 -> 0 | D51: =SUMIFS('Cash Balance'!$L$4:$L$920,'Cash Balance'!$W$4:$W$920,Summary!D$32,'Cash Balance'!$Y$4:$Y$920,Summary!$A51)/Fx_rate/1000000+SUMIFS('Cash Balance'!$T$4:$T$920,'Cash Balance'!$W$4:$W$920,Summary!D$32,'Cash Balance'!$Y$4:$Y$920,Summary!$A51)/1000000 -> 0 | E51: =SUM(B51:D51) -> 0 | F51: =E51/$E$63 -> 0
A52: OCB | B52: =SUMIFS(Table11[CLOSING BALANCE (VND)2],Table11[NAME],Summary!B$32,Table11[Bank_1],Summary!$A52)/Fx_rate/1000000+SUMIFS(Table11[CLOSING BALANCE (USD)],Table11[NAME],Summary!B$32,Table11[Bank_1],Summary!$A52)/1000000 -> 0.0028100769 | C52: =SUMIFS(Table11[CLOSING BALANCE (VND)2],Table11[NAME],Summary!C$32,Table11[Bank_1],Summary!$A52)/Fx_rate/1000000+SUMIFS(Table11[CLOSING BALANCE (USD)],Table11[NAME],Summary!C$32,Table11[Bank_1],Summary!$A52)/1000000 -> 0.0022579054 | D52: =SUMIFS(Table11[CLOSING BALANCE (VND)2],Table11[NAME],Summary!D$32,Table11[Bank_1],Summary!$A52)/Fx_rate/1000000+SUMIFS(Table11[CLOSING BALANCE (USD)],Table11[NAME],Summary!D$32,Table11[Bank_1],Summary!$A52)/1000000 -> 0.018052283 | E52: =SUM(B52:D52) -> 0.023120266 | F52: =E52/$E$63 -> 0.00014258903
A53: MBB | B53: =SUMIFS(Table11[CLOSING BALANCE (VND)2],Table11[NAME],Summary!B$32,Table11[Bank_1],Summary!$A53)/Fx_rate/1000000+SUMIFS(Table11[CLOSING BALANCE (USD)],Table11[NAME],Summary!B$32,Table11[Bank_1],Summary!$A53)/1000000 -> 0 | C53: =SUMIFS(Table11[CLOSING BALANCE (VND)2],Table11[NAME],Summary!C$32,Table11[Bank_1],Summary!$A53)/Fx_rate/1000000+SUMIFS(Table11[CLOSING BALANCE (USD)],Table11[NAME],Summary!C$32,Table11[Bank_1],Summary!$A53)/1000000 -> 0.00039404218 | D53: =SUMIFS(Table11[CLOSING BALANCE (VND)2],Table11[NAME],Summary!D$32,Table11[Bank_1],Summary!$A53)/Fx_rate/1000000+SUMIFS(Table11[CLOSING BALANCE (USD)],Table11[NAME],Summary!D$32,Table11[Bank_1],Summary!$A53)/1000000 -> 0 | E53: =SUM(B53:D53) -> 0.00039404218 | F53: =E53/$E$63 -> 2.4301663e-06
A54: VIB | B54: =SUMIFS(Table11[CLOSING BALANCE (VND)2],Table11[NAME],Summary!B$32,Table11[Bank_1],Summary!$A54)/Fx_rate/1000000+SUMIFS(Table11[CLOSING BALANCE (USD)],Table11[NAME],Summary!B$32,Table11[Bank_1],Summary!$A54)/1000000 -> 0.00057396512 | C54: =SUMIFS(Table11[CLOSING BALANCE (VND)2],Table11[NAME],Summary!C$32,Table11[Bank_1],Summary!$A54)/Fx_rate/1000000+SUMIFS(Table11[CLOSING BALANCE (USD)],Table11[NAME],Summary!C$32,Table11[Bank_1],Summary!$A54)/1000000 -> 6.5020148 | D54: =SUMIFS(Table11[CLOSING BALANCE (VND)2],Table11[NAME],Summary!D$32,Table11[Bank_1],Summary!$A54)/Fx_rate/1000000+SUMIFS(Table11[CLOSING BALANCE (USD)],Table11[NAME],Summary!D$32,Table11[Bank_1],Summary!$A54)/1000000 -> 0.16024829 | E54: =SUM(B54:D54) -> 6.662837 | F54: =E54/$E$63 -> 0.041091545
A55: DB - Singapore | B55: =SUMIFS(Table11[CLOSING BALANCE (VND)2],Table11[NAME],Summary!B$32,Table11[BRANCH],Summary!$A55)/Fx_rate/1000000+SUMIFS(Table11[CLOSING BALANCE (USD)],Table11[NAME],Summary!B$32,Table11[BRANCH],Summary!$A55)/1000000 -> 0 | C55: =SUMIFS(Table11[CLOSING BALANCE (VND)2],Table11[NAME],Summary!C$32,Table11[BRANCH],Summary!$A55)/Fx_rate/1000000+SUMIFS(Table11[CLOSING BALANCE (USD)],Table11[NAME],Summary!C$32,Table11[BRANCH],Summary!$A55)/1000000 -> 0 | D55: =SUMIFS(Table11[CLOSING BALANCE (VND)2],Table11[NAME],Summary!D$32,Table11[BRANCH],Summary!$A55)/Fx_rate/1000000+SUMIFS(Table11[CLOSING BALANCE (USD)],Table11[NAME],Summary!D$32,Table11[BRANCH],Summary!$A55)/1000000 -> 0 | E55: =SUM(B55:D55) -> 0 | F55: =E55/$E$63 -> 0
...

Sheet >>Breakdown

Sheet >>>Detail

Sheet Current_Yield
H2: =H4=Summary!B122*Fx_rate -> FALSE
A3: Original Currency: VND | B3: BWID JSC | C3: Yield | D3: VC3 | E3: Yield | F3: Subsidiaries | G3: Yield | H3: Total (VND) | I3: Weighted average deposit rate | J3: Remark
A4: Current Yield Deposit | B4: =SUM(B5:B17) -> 2661564578 | C4: =SUMPRODUCT(B5:B17,C5:C17)/B4 -> 0.0034058072 | D4: =SUM(D5:D17) -> 355152665621 | E4: =SUMPRODUCT(D5:D17,E5:E17)/D4 -> 0.004779879 | F4: =SUM(F5:F17) -> 536870155427 | G4: =SUMPRODUCT(F5:F17,G5:G17)/F4 -> 0.0046556406 | H4: =SUM(B4,D4,F4) -> 894684385626 | I4: =IFERROR((B4*C4+D4*E4+F4*G4)/H4,0) -> 0.00470124
A5: VTB | B5: =SUMIFS(Table11[CLOSING BALANCE (VND)2],Table11[NAME],B$3,Table11[Bank_1],$A5,Table11[ACCOUNT TYPE],"<>Saving Account") -> 1092828338 | C5: 0.005 | D5: =SUMIFS(Table11[CLOSING BALANCE (VND)2],Table11[NAME],D$3,Table11[Bank_1],$A5,Table11[ACCOUNT TYPE],"<>Saving Account") -> 323739882218 | E5: 0.005 | F5: =SUMIFS(Table11[CLOSING BALANCE (VND)2],Table11[NAME],F$3,Table11[Bank_1],$A5,Table11[ACCOUNT TYPE],"<>Saving Account") -> 257416245151 | G5: 0.005 | H5: =SUM(B5,D5,F5) -> 582248955707 | I5: =IFERROR((B5*C5+D5*E5+F5*G5)/H5,0) -> 0.005
A6: VCB | B6: =SUMIFS(Table11[CLOSING BALANCE (VND)2],Table11[NAME],B$3,Table11[Bank_1],$A6,Table11[ACCOUNT TYPE],"<>Saving Account") -> 511704863 | C6: 0.005 | D6: =SUMIFS(Table11[CLOSING BALANCE (VND)2],Table11[NAME],D$3,Table11[Bank_1],$A6,Table11[ACCOUNT TYPE],"<>Saving Account") -> 9871359781 | E6: 0.005 | F6: =SUMIFS(Table11[CLOSING BALANCE (VND)2],Table11[NAME],F$3,Table11[Bank_1],$A6,Table11[ACCOUNT TYPE],"<>Saving Account") -> 100658315230 | G6: 0.005 | H6: =SUM(B6,D6,F6) -> 111041379874 | I6: =IFERROR((B6*C6+D6*E6+F6*G6)/H6,0) -> 0.005
A7: BIDV | B7: =SUMIFS(Table11[CLOSING BALANCE (VND)2],Table11[NAME],B$3,Table11[Bank_1],$A7,Table11[ACCOUNT TYPE],"<>Saving Account") -> 38060079 | C7: 0.005 | D7: =SUMIFS(Table11[CLOSING BALANCE (VND)2],Table11[NAME],D$3,Table11[Bank_1],$A7,Table11[ACCOUNT TYPE],"<>Saving Account") -> 5452129673 | E7: 0.005 | F7: =SUMIFS(Table11[CLOSING BALANCE (VND)2],Table11[NAME],F$3,Table11[Bank_1],$A7,Table11[ACCOUNT TYPE],"<>Saving Account") -> 99745278620 | G7: 0.005 | H7: =SUM(B7,D7,F7) -> 105235468372 | I7: =IFERROR((B7*C7+D7*E7+F7*G7)/H7,0) -> 0.005
A8: VIB | B8: =SUMIFS(Table11[CLOSING BALANCE (VND)2],Table11[NAME],B$3,Table11[Bank_1],$A8,Table11[ACCOUNT TYPE],"<>Saving Account") -> 13672907 | C8: 0.005 | D8: =SUMIFS(Table11[CLOSING BALANCE (VND)2],Table11[NAME],D$3,Table11[Bank_1],$A8,Table11[ACCOUNT TYPE],"<>Saving Account") -> 187619615 | E8: 0.005 | F8: =SUMIFS(Table11[CLOSING BALANCE (VND)2],Table11[NAME],F$3,Table11[Bank_1],$A8,Table11[ACCOUNT TYPE],"<>Saving Account") -> 1594498896 | G8: 0.005 | H8: =SUM(B8,D8,F8) -> 1795791418 | I8: =IFERROR((B8*C8+D8*E8+F8*G8)/H8,0) -> 0.005
A9: OCB | B9: =SUMIFS(Table11[CLOSING BALANCE (VND)2],Table11[NAME],B$3,Table11[Bank_1],$A9,Table11[ACCOUNT TYPE],"<>Saving Account") -> 69627514 | C9: 0.001 | D9: =SUMIFS(Table11[CLOSING BALANCE (VND)2],Table11[NAME],D$3,Table11[Bank_1],$A9,Table11[ACCOUNT TYPE],"<>Saving Account") -> 56483173 | E9: 0.001 | F9: =SUMIFS(Table11[CLOSING BALANCE (VND)2],Table11[NAME],F$3,Table11[Bank_1],$A9,Table11[ACCOUNT TYPE],"<>Saving Account") -> 472518514 | G9: 0.001 | H9: =SUM(B9,D9,F9) -> 598629201 | I9: =IFERROR((B9*C9+D9*E9+F9*G9)/H9,0) -> 0.001
A10: MBB | B10: =SUMIFS(Table11[CLOSING BALANCE (VND)2],Table11[NAME],B$3,Table11[Bank_1],$A10,Table11[ACCOUNT TYPE],"<>Saving Account") -> 0 | D10: =SUMIFS(Table11[CLOSING BALANCE (VND)2],Table11[NAME],D$3,Table11[Bank_1],$A10,Table11[ACCOUNT TYPE],"<>Saving Account") -> 7958304 | E10: 0.001 | F10: =SUMIFS(Table11[CLOSING BALANCE (VND)2],Table11[NAME],F$3,Table11[Bank_1],$A10,Table11[ACCOUNT TYPE],"<>Saving Account") -> 0 | G10: 0.001 | H10: =SUM(B10,D10,F10) -> 7958304 | I10: =IFERROR((B10*C10+D10*E10+F10*G10)/H10,0) -> 0.001
A11: DB - Singapore | B11: =SUMIFS(Table11[CLOSING BALANCE (VND)2],Table11[NAME],B$3,Table11[Bank_1],$A11,Table11[ACCOUNT TYPE],"<>Saving Account") -> 0 | D11: =SUMIFS(Table11[CLOSING BALANCE (VND)2],Table11[NAME],D$3,Table11[Bank_1],$A11,Table11[ACCOUNT TYPE],"<>Saving Account") -> 0 | F11: =SUMIFS(Table11[CLOSING BALANCE (VND)2],Table11[NAME],F$3,Table11[Bank_1],$A11,Table11[ACCOUNT TYPE],"<>Saving Account") -> 0 | H11: =SUM(B11,D11,F11) -> 0 | I11: =IFERROR((B11*C11+D11*E11+F11*G11)/H11,0) -> 0
A12: SNP | B12: =SUMIFS(Table11[CLOSING BALANCE (VND)2],Table11[NAME],B$3,Table11[Bank_1],$A12,Table11[ACCOUNT TYPE],"<>Saving Account") -> 613468682 | D12: =SUMIFS(Table11[CLOSING BALANCE (VND)2],Table11[NAME],D$3,Table11[Bank_1],$A12,Table11[ACCOUNT TYPE],"<>Saving Account") -> 74818921 | F12: =SUMIFS(Table11[CLOSING BALANCE (VND)2],Table11[NAME],F$3,Table11[Bank_1],$A12,Table11[ACCOUNT TYPE],"<>Saving Account") -> 8987894766 | G12: 0.003 | H12: =SUM(B12,D12,F12) -> 9676182369 | I12: =IFERROR((B12*C12+D12*E12+F12*G12)/H12,0) -> 0.0027866036
A13: ACB | B13: =SUMIFS(Table11[CLOSING BALANCE (VND)2],Table11[NAME],B$3,Table11[Bank_1],$A13,Table11[ACCOUNT TYPE],"<>Saving Account") -> 69320954 | C13: 0.005 | D13: =SUMIFS(Table11[CLOSING BALANCE (VND)2],Table11[NAME],D$3,Table11[Bank_1],$A13,Table11[ACCOUNT TYPE],"<>Saving Account") -> 253471960 | E13: 0.005 | F13: =SUMIFS(Table11[CLOSING BALANCE (VND)2],Table11[NAME],F$3,Table11[Bank_1],$A13,Table11[ACCOUNT TYPE],"<>Saving Account") -> 110047453 | G13: 0.005 | H13: =SUM(B13,D13,F13) -> 432840367 | I13: =IFERROR((B13*C13+D13*E13+F13*G13)/H13,0) -> 0.005
A14: TCB | B14: =SUMIFS(Table11[CLOSING BALANCE (VND)2],Table11[NAME],B$3,Table11[Bank_1],$A14,Table11[ACCOUNT TYPE],"<>Saving Account") -> 1367012 | C14: 0.005 | D14: =SUMIFS(Table11[CLOSING BALANCE (VND)2],Table11[NAME],D$3,Table11[Bank_1],$A14,Table11[ACCOUNT TYPE],"<>Saving Account") -> 1560960116 | F14: =SUMIFS(Table11[CLOSING BALANCE (VND)2],Table11[NAME],F$3,Table11[Bank_1],$A14,Table11[ACCOUNT TYPE],"<>Saving Account") -> 13875586656 | G14: 0.005 | H14: =SUM(B14,D14,F14) -> 15437913784 | I14: =IFERROR((B14*C14+D14*E14+F14*G14)/H14,0) -> 0.0044944394
A15: Standard Chartered | B15: =SUMIFS(Table11[CLOSING BALANCE (VND)2],Table11[NAME],B$3,Table11[Bank_1],$A15,Table11[ACCOUNT TYPE],"<>Saving Account") -> 0 | C15: 0 | D15: =SUMIFS(Table11[CLOSING BALANCE (VND)2],Table11[NAME],D$3,Table11[Bank_1],$A15,Table11[ACCOUNT TYPE],"<>Saving Account") -> 0 | E15: 0 | F15: =SUMIFS(Table11[CLOSING BALANCE (VND)2],Table11[NAME],F$3,Table11[Bank_1],$A15,Table11[ACCOUNT TYPE],"<>Saving Account") -> 1465849798 | G15: 0 | H15: =SUM(B15,D15,F15) -> 1465849798 | I15: 0
A16: UOB | B16: =SUMIFS(Table11[CLOSING BALANCE (VND)2],Table11[NAME],B$3,Table11[Bank_1],$A16,Table11[ACCOUNT TYPE],"<>Saving Account") -> 71325444 | C16: 0 | D16: =SUMIFS(Table11[CLOSING BALANCE (VND)2],Table11[NAME],D$3,Table11[Bank_1],$A16,Table11[ACCOUNT TYPE],"<>Saving Account") -> 13300634401 | E16: 0 | F16: =SUMIFS(Table11[CLOSING BALANCE (VND)2],Table11[NAME],F$3,Table11[Bank_1],$A16,Table11[ACCOUNT TYPE],"<>Saving Account") -> 24708146 | G16: 0 | H16: =SUM(B16,D16,F16) -> 13396667991 | I16: 0
A17: Others | B17: =SUMIFS(Table11[CLOSING BALANCE (VND)2],Table11[NAME],B$3,Table11[Bank_1],$A17,Table11[ACCOUNT TYPE],"<>Saving Account") -> 180188785 | C17: 0.002 | D17: =SUMIFS(Table11[CLOSING BALANCE (VND)2],Table11[NAME],D$3,Table11[Bank_1],$A17,Table11[ACCOUNT TYPE],"<>Saving Account") -> 647347459 | E17: 0 | F17: =SUMIFS(Table11[CLOSING BALANCE (VND)2],Table11[NAME],F$3,Table11[Bank_1],$A17,Table11[ACCOUNT TYPE],"<>Saving Account") -> 52519212197 | G17: 0.002 | H17: =SUM(B17,D17,F17) -> 53346748441 | I17: =IFERROR((B17*C17+D17*E17+F17*G17)/H17,0) -> 0.0019757306
A18: Total | B18: =SUM(B5:B17) -> 2661564578 | D18: =SUM(D5:D17) -> 355152665621 | F18: =SUM(F5:F17) -> 536870155427 | H18: =SUM(H5:H17) -> 894684385626

Sheet VND_rate
